<!DOCTYPE html>
<html lang="en">

<head>
  <meta charset="UTF-8">
  <meta http-equiv="X-UA-Compatible" content="IE=edge">
  <meta name="viewport" content="width=device-width, initial-scale=1.0">
  <title>Document</title>
</head>

<body>
  <script>
    // test01
    function strFun(str) {
      return new Promise((resolve, reject) => {
        if(str.length > 5){
          console.log(str);
          anotherStr = 'Good!';
          return resolve(anotherStr); // 异步操作成功时调用，将异步操作的结果作为参数传递出去
          console.log('after resolve') 
          // resolve只是修改状态，它之后的代码依然会执行，并且由于是同步代码，会在promise的then之前执行
          // 推荐在resolve前加return，这样确保resolve之后的代码不执行，避免意外
        }
        else{
          console.log(str + ': This string is too short!');
          return reject('Bad!'); // 在异步操作失败时调用，并将异步操作报出的错误，作为参数传递出去。
        }
      })
    }

    strFun('Hello World!').then((anotherStr) => {
      console.log(anotherStr); // 'Good!'
    },(err) => {
      console.error(err);
    })

    strFun('Hi!').then((anotherStr) => {
      console.log(anotherStr);
    },(err) => {
      console.error(err); // 'Bad!'
    })

    // test02
    function timeOut(ms) {
      return new Promise((resolve, reject) => {
        setTimeout(resolve, ms, 'Done!'); // 第三个参数是向回调函数(第一个参数)中传入的参数
      })
    }

    timeOut(2000).then((value) => {
      console.log(value);
    })

    //test03
    const p1 = new Promise((resolve, reject) => {
      setTimeout(() => {
        return reject(new Error('Fail!'))
      }, 3000);
    })

    const p2 = new Promise((resolve, reject) => {
      setTimeout(() => {
        return resolve(p1); 
        // 由于p2的resolve的参数是promise，导致自己的状态无效化
        // p2的真实状态由p1决定，而p1在3s后状态变为reject，因此p2的状态在3s后变为reject
      }, 1000);
    })

    p2
      .then((msg) => {
        console.log(msg);
      }) 
      .catch((err) => {
        console.error(err); // Fail!
      })

      // test04

      // 很普通的的链式调用
      const strArr = ['How are you', 'Fine thank you', 'Nice to meet you']; 
      strFun(strArr[0]).then(
        () => {
          strFun(strArr[1]);
        },
        (err) => {
          console.error(err);
        }
      ).then(
        () => {
          strFun(strArr[2]);
          return 114514; // 返回结果会作为参数，传入下一个回调函数
        },
        (err) => {
          console.error(err);
        }
      ).then(
        (msg) => {
          console.log(msg); // 114514
        }
      )
      // 采用链式的then，可以指定一组按照次序调用的回调函数。这时，前一个回调函数，
      // 有可能返回的还是一个Promise对象（即有异步操作），
      // 这时后一个回调函数，就会等待该Promise对象的状态发生变化，才会被调用。

      // 关于Promise.catch

      // Promise 对象的错误具有“冒泡”性质，会一直向后传递，直到被捕获为止。
      // 也就是说，错误总是会被下一个catch语句捕获。
      // 一般来说，不要在then()方法里面定义 Reject 状态的回调函数，总是使用catch方法。
      // 原因：可以捕获前边then方法执行中的错误，也更接近同步的写法

      // test05

      // finally方法的回调函数不接受任何参数
      // finally方法里面的操作，应该是与状态无关的，不依赖于 Promise 的执行结果
      strFun('I love u, u love me, mexue ice-cream and tea~').finally(
        () => {
          console.log('OK'); // OK
        }
      )
      strFun('lmao').finally(
        () => {
          console.log('OK'); // OK
        }
      )
      
  </script>
</body>

</html>